# 에러 핸들링

## 'try..catch'와 에러 핸들링

에러가 있는 스크립트는 아무리 실력좋은 프로그래머 나올 수 밖에 없다.
모든 것은 실수나 예상치 못한 입력값, 잘못된 서버의 응답이 될 수 있다.

자바스크립트에서 에러가 발생하면 즉시 중단하고, 콘솔에 에러를 출력합니다.
하지만, try catch를 통해 스크립트의 중단을 방지하고 더 합당한 동작을 지정하는 것이 에러 핸들리의 주요한 부분이다.

try…catch 동작 알고리즘은 다음과 같다.

1. 먼저, try {...} 안의 코드가 실행한다.
2. 에러가 없다면, try 안의 마지막 줄까지 실행되고, catch 블록은 건너뛴다.
3. 에러가 있다면, try 안 코드의 실행이 중단되고, catch(err) 블록으로 제어 흐름이 넘어간다. 변수 err(아무 이름이나 사용 가능)는 무슨 일이 일어났는지에 대한 설명이 담긴 에러 객체를 포함하고 있다.

### try catch는 오직 런타입 에러에만 동작하며, 동기적으로 동작한다.

자바스크립트 엔진은 코드를 읽고 난 후 코드를 실행한다. 코드를 읽는 중에 발생하는 에러는 `'parse-time 에러’`라고 부르는데, 엔진은 이 코드를 이해할 수 없기 때문에 `parse-time` 에러는 코드 안에서 복구가 불가능하다.

`setTimeout`처럼 `‘스케줄 된(scheduled)’` 코드에서 발생한 예외는 `try..catch`에서 잡아낼 수 없다.
스케줄 된 함수 내부의 예외를 잡으려면, `try..catch`를 반드시 함수 내부에 구현해야 한다.

### 에러 객체

에러가 발생하면 자바스크립트는 에러 상세 내용을 담긴 객체를 생성하여, catch 블록에 이 객체를 인수로 전달한다.

에러객체의 주요 프로퍼티로는 아래와 같다.

- name : 에러이름, 정의되지 않은 변수인 경우 ReferenceError가 이름이 된다.
- message : 에러 상세 내용을 담고 있는 문자메시지

- stack(비표준 프로퍼티) : 현재 호출된 스택. 에러를 유발한 중첩 호출들의 순서정보를 가진 문자열로 디버깅 목적으로 사용한다.

선택적 catch로 자세한 정보가 필요없다면 catch에서 이를 생략할 수 있다.

### try catch 활용법

전달받은 데이터에 JSON.parse를 호출하는 식으로 사용하는 경우가 있다.

```js
let json = '{"name":"John", "age": 30}'; // 서버로부터 전달받은 데이터

let user = JSON.parse(json); // 전달받은 문자열을 자바스크립트 객체로 변환

// 문자열 형태로 전달받은 user가 프로퍼티를 가진 객체가 됨
alert(user.name); // John
alert(user.age); // 30
```

잘못된 형식의 json이 들어온 경우, JSON.parse는 에러를 만들기 때문에 스크립트가 죽는다. 이를 try catch를 통해 처리할 수 있다.

```js
let json = "{ bad json }";

try {
  let user = JSON.parse(json); // <-- 여기서 에러가 발생하므로
  alert(user.name); // 이 코드는 동작하지 않습니다.
} catch (e) {
  // 에러가 발생하면 제어 흐름이 catch 문으로 넘어옵니다.
  alert("데이터에 에러가 있어 재요청을 시도합니다.");
  alert(e.name);
  alert(e.message);
}
```

catch에 대해서 다시 에러를 던질 수도 있다.

```js
try {
  user = {
    /*...*/
  };
} catch (err) {
  if (err instanceof ReferenceError) {
    alert("ReferenceError"); //  정의되지 않은 변수에 접근하여 'ReferenceError' 발생
  }
}
```

### finally

finally안의 코드는 다음과 같은 상황에서 실행된다.

```js
try {
   ... 코드를 실행 ...
} catch(e) {
   ... 에러 핸들링 ...
} finally {
   ... 항상 실행 ...
}
```

finally 절은 무언가를 실행하고, 실행 결과에 상관없이 실행을 완료하고 싶을 경우 사용한다.
try..catch..finally 안의 변수는 지역 변수이다.

### 전역 catch

전역 핸들러 `window.onerror`는 죽어버린 스크립트를 복구하려는 목적보다는 개발자에게 에러 메시지를 보내는 용도로 사용한다.

## 커스텀 에러와 에러 확장

에러 클래스가 필요한 경우가 종종 생긴다. 네트워크 관련 작업 중 에러가 발생했다면 `HttpError`, 데이터베이스 관련 작업 중 에러가 발생했다면 `DbError`, 검색 관련 작업 중 에러가 발생한다.

직접 에러 클래스를 만든 경우, 이 에러들은 `message`이나 `name`, 가능하다면 `stack` 프로퍼티를 지원해야 한다. 물론 이런 프로퍼티 이외에도 다른 프로퍼티를 지원할 수 있다.
`HttpError` 클래스의 객체에 `statusCode` 프로퍼티를 만들고 `404`나 `403`, `500`같은 숫자를 값으로 지정할 수 있다.

### 에러 확장하기

내가 읽어드리는 에러에 대해서 형식에 대해서 새로운 클래스를 통해 에러를 확장할 수 있다.
이제 ValidationError에서 Error를 상속을 통하는 예시는 다음과 같다.

```js
class ValidationError extends Error {
  constructor(message) {
    super(message); // (1)
    this.name = "ValidationError"; // (2)
  }
}

function test() {
  throw new ValidationError("에러 발생!");
}

try {
  test();
} catch (err) {
  alert(err.message); // 에러 발생!
  alert(err.name); // ValidationError
  alert(err.stack); // 각 행 번호가 있는 중첩된 호출들의 목록
}

// 사용법
function readUser(json) {
  let user = JSON.parse(json);

  if (!user.age) {
    throw new ValidationError("No field: age");
  }
  if (!user.name) {
    throw new ValidationError("No field: name");
  }

  return user;
}

// try..catch와 readUser를 함께 사용한 예시

try {
  let user = readUser('{ "age": 25 }');
} catch (err) {
  if (err instanceof ValidationError) {
    alert("Invalid data: " + err.message); // Invalid data: No field: name
  } else if (err instanceof SyntaxError) {
    // (*)
    alert("JSON Syntax Error: " + err.message);
  } else {
    throw err; // 알려지지 않은 에러는 재던지기 합니다. (**)
  }
}
```

`(1)`에서 부모 생성자를 호출하고 있는 것처럼, 자바스크립트에서는 자식 생성자 안에서 `super`를 반드시 호출해야 한다. `message` 프로퍼티는 부모 생성자에서 설정된다.
커스텀 에러 `ValidationError`와 `JSON.parse`에서 발생하는 `SyntaxError` 둘 다를 처리할수 있다.

### 더 깊게 상속하기

꼭 필요한 프로퍼티가 누락되거나 age에 문자열 값이 들어가는 것처럼 형식이 잘못된 경우를 처리할 수 없다.
좀 더 구체적인 클래스 PropertyRequiredError를 생성해보는 예시가 있다.

```js
class ValidationError extends Error {
  constructor(message) {
    super(message);
    this.name = "ValidationError";
  }
}

class PropertyRequiredError extends ValidationError {
  constructor(property) {
    super("No property: " + property);
    this.name = "PropertyRequiredError";
    this.property = property;
  }
}

// try..catch와 readUser를 함께 사용하면 다음과 같습니다.

try {
  let user = readUser('{ "age": 25 }');
} catch (err) {
  if (err instanceof ValidationError) {
    alert("Invalid data: " + err.message); // Invalid data: No property: name
    alert(err.name); // PropertyRequiredError
    alert(err.property); // name
  } else if (err instanceof SyntaxError) {
    alert("JSON Syntax Error: " + err.message);
  } else {
    throw err; // 알려지지 않은 에러는 재던지기.
  }
}
```

`new PropertyRequiredError(property)`처럼 프로퍼티 이름을 전달하기만 하면 된다.

### 예외 감싸기

앞으로 readUser가 더 커지면 다른 커스텀 에러 클래스를 만들어야 함을 예상 해보자.
"미래에 readUser 기능이 커지면서 에러 종류가 많아질 텐데 그때마다 에러 종류에 따라 에러 처리 분기문을 매번 추가해야 하나?" 라는 생각이 들 수 있다.

실제 우리가 필요로 하는 정보는 ‘데이터를 읽을 때’ 에러가 발생했는지에 대한 여부이다. 왜 에러가 발생했는지와 자세한 설명은 대부분의 경우 필요하지 않다. 필요할 때 에러 세부사항에 대한 정보를 얻을 수 있는 방법을 이 있다면 좋을 거다.

이런 에러 처리 기술은 '예외 감싸기(wrapping exception)'라고 부른다.

예외 감싸기를 적용한 함수에선 모든 에러를 종류별로 처리하지 않는다. 대신 모든 에러를 포함할 수 있는 추상 에러를 하나 만들고, 에러가 발생하면 이 추상 에러를 던지도록 한다.

